2025-03-11 16:53:01,977 ERROR: Exception on /favicon.ico [GET] [in /Users/malandru/.pyenv/versions/3.13.1/lib/python3.13/site-packages/flask/app.py:875]
Traceback (most recent call last):
  File "/Users/malandru/.pyenv/versions/3.13.1/lib/python3.13/site-packages/flask/app.py", line 917, in full_dispatch_request
    rv = self.dispatch_request()
  File "/Users/malandru/.pyenv/versions/3.13.1/lib/python3.13/site-packages/flask/app.py", line 891, in dispatch_request
    self.raise_routing_exception(req)
    ~~~~~~~~~~~~~~~~~~~~~~~~~~~~^^^^^
  File "/Users/malandru/.pyenv/versions/3.13.1/lib/python3.13/site-packages/flask/app.py", line 500, in raise_routing_exception
    raise request.routing_exception  # type: ignore[misc]
    ^^^^^^^^^^^^^^^^^^^^^^^^^^^^^^^
  File "/Users/malandru/.pyenv/versions/3.13.1/lib/python3.13/site-packages/flask/ctx.py", line 362, in match_request
    result = self.url_adapter.match(return_rule=True)  # type: ignore
  File "/Users/malandru/.pyenv/versions/3.13.1/lib/python3.13/site-packages/werkzeug/routing/map.py", line 629, in match
    raise NotFound() from None
werkzeug.exceptions.NotFound: 404 Not Found: The requested URL was not found on the server. If you entered the URL manually please check your spelling and try again.

During handling of the above exception, another exception occurred:

Traceback (most recent call last):
  File "/Users/malandru/.pyenv/versions/3.13.1/lib/python3.13/site-packages/flask/app.py", line 1511, in wsgi_app
    response = self.full_dispatch_request()
  File "/Users/malandru/.pyenv/versions/3.13.1/lib/python3.13/site-packages/flask/app.py", line 919, in full_dispatch_request
    rv = self.handle_user_exception(e)
  File "/Users/malandru/.pyenv/versions/3.13.1/lib/python3.13/site-packages/flask/app.py", line 802, in handle_user_exception
    return self.handle_http_exception(e)
           ~~~~~~~~~~~~~~~~~~~~~~~~~~^^^
  File "/Users/malandru/.pyenv/versions/3.13.1/lib/python3.13/site-packages/flask/app.py", line 777, in handle_http_exception
    return self.ensure_sync(handler)(e)  # type: ignore[no-any-return]
           ~~~~~~~~~~~~~~~~~~~~~~~~~^^^
  File "/Users/malandru/microblog_2.0/app/errors.py", line 6, in not_found_error
    return render_template('404.html'), 404
           ~~~~~~~~~~~~~~~^^^^^^^^^^^^
  File "/Users/malandru/.pyenv/versions/3.13.1/lib/python3.13/site-packages/flask/templating.py", line 150, in render_template
    return _render(app, template, context)
  File "/Users/malandru/.pyenv/versions/3.13.1/lib/python3.13/site-packages/flask/templating.py", line 131, in _render
    rv = template.render(context)
  File "/Users/malandru/.pyenv/versions/3.13.1/lib/python3.13/site-packages/jinja2/environment.py", line 1295, in render
    self.environment.handle_exception()
    ~~~~~~~~~~~~~~~~~~~~~~~~~~~~~~~~~^^
  File "/Users/malandru/.pyenv/versions/3.13.1/lib/python3.13/site-packages/jinja2/environment.py", line 942, in handle_exception
    raise rewrite_traceback_stack(source=source)
  File "/Users/malandru/microblog_2.0/app/templates/404.html", line 1, in top-level template code
    {% extends "base.html" %} {% block content %}
    ^^^^^^^^^^^^^^^^^^^^^^^^^
  File "/Users/malandru/microblog_2.0/app/templates/base.html", line 58, in top-level template code
    {{ moment.include_moment() }}
    ^^^^^^^^^^^^^^^^^^^
  File "/Users/malandru/.pyenv/versions/3.13.1/lib/python3.13/site-packages/jinja2/environment.py", line 490, in getattr
    return getattr(obj, attribute)
jinja2.exceptions.UndefinedError: 'moment' is undefined
2025-03-11 16:53:22,098 INFO: Microblog startup [in /Users/malandru/microblog_2.0/app/__init__.py:58]
2025-03-11 16:53:23,714 ERROR: Exception on / [GET] [in /Users/malandru/.pyenv/versions/3.13.1/lib/python3.13/site-packages/flask/app.py:875]
Traceback (most recent call last):
  File "/Users/malandru/.pyenv/versions/3.13.1/lib/python3.13/site-packages/flask/app.py", line 1511, in wsgi_app
    response = self.full_dispatch_request()
  File "/Users/malandru/.pyenv/versions/3.13.1/lib/python3.13/site-packages/flask/app.py", line 919, in full_dispatch_request
    rv = self.handle_user_exception(e)
  File "/Users/malandru/.pyenv/versions/3.13.1/lib/python3.13/site-packages/flask/app.py", line 917, in full_dispatch_request
    rv = self.dispatch_request()
  File "/Users/malandru/.pyenv/versions/3.13.1/lib/python3.13/site-packages/flask/app.py", line 902, in dispatch_request
    return self.ensure_sync(self.view_functions[rule.endpoint])(**view_args)  # type: ignore[no-any-return]
           ~~~~~~~~~~~~~~~~~~~~~~~~~~~~~~~~~~~~~~~~~~~~~~~~~~~~^^^^^^^^^^^^^
  File "/Users/malandru/.pyenv/versions/3.13.1/lib/python3.13/site-packages/flask_login/utils.py", line 290, in decorated_view
    return current_app.ensure_sync(func)(*args, **kwargs)
           ~~~~~~~~~~~~~~~~~~~~~~~~~~~~~^^^^^^^^^^^^^^^^^
  File "/Users/malandru/microblog_2.0/app/routes.py", line 36, in index
    return render_template('index.html', title='Home', form=form,
                           posts=posts.items, next_url=next_url,
                           prev_url=prev_url)
  File "/Users/malandru/.pyenv/versions/3.13.1/lib/python3.13/site-packages/flask/templating.py", line 150, in render_template
    return _render(app, template, context)
  File "/Users/malandru/.pyenv/versions/3.13.1/lib/python3.13/site-packages/flask/templating.py", line 131, in _render
    rv = template.render(context)
  File "/Users/malandru/.pyenv/versions/3.13.1/lib/python3.13/site-packages/jinja2/environment.py", line 1295, in render
    self.environment.handle_exception()
    ~~~~~~~~~~~~~~~~~~~~~~~~~~~~~~~~~^^
  File "/Users/malandru/.pyenv/versions/3.13.1/lib/python3.13/site-packages/jinja2/environment.py", line 942, in handle_exception
    raise rewrite_traceback_stack(source=source)
  File "/Users/malandru/microblog_2.0/app/templates/index.html", line 1, in top-level template code
    {% extends "base.html" %} {% import "bootstrap_wtf.html" as wtf %} {% block
    ^^^^^^^^^^^^^^^^^^^^^^^^^
  File "/Users/malandru/microblog_2.0/app/templates/base.html", line 58, in top-level template code
    {{ moment.include_moment() }}
    ^^^^^^^^^^^^^^^^^^^
  File "/Users/malandru/.pyenv/versions/3.13.1/lib/python3.13/site-packages/jinja2/environment.py", line 490, in getattr
    return getattr(obj, attribute)
jinja2.exceptions.UndefinedError: 'moment' is undefined
2025-03-11 16:54:59,517 INFO: Microblog startup [in /Users/malandru/microblog_2.0/app/__init__.py:50]
2025-03-11 16:56:34,240 INFO: Microblog startup [in /Users/malandru/microblog_2.0/app/__init__.py:50]
