2025-03-11 11:47:29,956 ERROR: Exception on /login [POST] [in /Users/malandru/.pyenv/versions/3.13.1/lib/python3.13/site-packages/flask/app.py:875]
Traceback (most recent call last):
  File "/Users/malandru/.pyenv/versions/3.13.1/lib/python3.13/site-packages/sqlalchemy/engine/base.py", line 1964, in _exec_single_context
    self.dialect.do_execute(
    ~~~~~~~~~~~~~~~~~~~~~~~^
        cursor, str_statement, effective_parameters, context
        ^^^^^^^^^^^^^^^^^^^^^^^^^^^^^^^^^^^^^^^^^^^^^^^^^^^^
    )
    ^
  File "/Users/malandru/.pyenv/versions/3.13.1/lib/python3.13/site-packages/sqlalchemy/engine/default.py", line 942, in do_execute
    cursor.execute(statement, parameters)
    ~~~~~~~~~~~~~~^^^^^^^^^^^^^^^^^^^^^^^
sqlite3.OperationalError: no such table: user

The above exception was the direct cause of the following exception:

Traceback (most recent call last):
  File "/Users/malandru/.pyenv/versions/3.13.1/lib/python3.13/site-packages/flask/app.py", line 1511, in wsgi_app
    response = self.full_dispatch_request()
  File "/Users/malandru/.pyenv/versions/3.13.1/lib/python3.13/site-packages/flask/app.py", line 919, in full_dispatch_request
    rv = self.handle_user_exception(e)
  File "/Users/malandru/.pyenv/versions/3.13.1/lib/python3.13/site-packages/flask/app.py", line 917, in full_dispatch_request
    rv = self.dispatch_request()
  File "/Users/malandru/.pyenv/versions/3.13.1/lib/python3.13/site-packages/flask/app.py", line 902, in dispatch_request
    return self.ensure_sync(self.view_functions[rule.endpoint])(**view_args)  # type: ignore[no-any-return]
           ~~~~~~~~~~~~~~~~~~~~~~~~~~~~~~~~~~~~~~~~~~~~~~~~~~~~^^^^^^^^^^^^^
  File "/Users/malandru/microblog_2.0/app/routes.py", line 63, in login
    user = db.session.scalar(
        sa.select(User).where(User.username == form.username.data))
  File "/Users/malandru/.pyenv/versions/3.13.1/lib/python3.13/site-packages/sqlalchemy/orm/scoping.py", line 1841, in scalar
    return self._proxied.scalar(
           ~~~~~~~~~~~~~~~~~~~~^
        statement,
        ^^^^^^^^^^
    ...<3 lines>...
        **kw,
        ^^^^^
    )
    ^
  File "/Users/malandru/.pyenv/versions/3.13.1/lib/python3.13/site-packages/sqlalchemy/orm/session.py", line 2413, in scalar
    return self._execute_internal(
           ~~~~~~~~~~~~~~~~~~~~~~^
        statement,
        ^^^^^^^^^^
    ...<4 lines>...
        **kw,
        ^^^^^
    )
    ^
  File "/Users/malandru/.pyenv/versions/3.13.1/lib/python3.13/site-packages/sqlalchemy/orm/session.py", line 2251, in _execute_internal
    result: Result[Any] = compile_state_cls.orm_execute_statement(
                          ~~~~~~~~~~~~~~~~~~~~~~~~~~~~~~~~~~~~~~~^
        self,
        ^^^^^
    ...<4 lines>...
        conn,
        ^^^^^
    )
    ^
  File "/Users/malandru/.pyenv/versions/3.13.1/lib/python3.13/site-packages/sqlalchemy/orm/context.py", line 305, in orm_execute_statement
    result = conn.execute(
        statement, params or {}, execution_options=execution_options
    )
  File "/Users/malandru/.pyenv/versions/3.13.1/lib/python3.13/site-packages/sqlalchemy/engine/base.py", line 1416, in execute
    return meth(
        self,
        distilled_parameters,
        execution_options or NO_OPTIONS,
    )
  File "/Users/malandru/.pyenv/versions/3.13.1/lib/python3.13/site-packages/sqlalchemy/sql/elements.py", line 515, in _execute_on_connection
    return connection._execute_clauseelement(
           ~~~~~~~~~~~~~~~~~~~~~~~~~~~~~~~~~^
        self, distilled_params, execution_options
        ^^^^^^^^^^^^^^^^^^^^^^^^^^^^^^^^^^^^^^^^^
    )
    ^
  File "/Users/malandru/.pyenv/versions/3.13.1/lib/python3.13/site-packages/sqlalchemy/engine/base.py", line 1638, in _execute_clauseelement
    ret = self._execute_context(
        dialect,
    ...<8 lines>...
        cache_hit=cache_hit,
    )
  File "/Users/malandru/.pyenv/versions/3.13.1/lib/python3.13/site-packages/sqlalchemy/engine/base.py", line 1843, in _execute_context
    return self._exec_single_context(
           ~~~~~~~~~~~~~~~~~~~~~~~~~^
        dialect, context, statement, parameters
        ^^^^^^^^^^^^^^^^^^^^^^^^^^^^^^^^^^^^^^^
    )
    ^
  File "/Users/malandru/.pyenv/versions/3.13.1/lib/python3.13/site-packages/sqlalchemy/engine/base.py", line 1983, in _exec_single_context
    self._handle_dbapi_exception(
    ~~~~~~~~~~~~~~~~~~~~~~~~~~~~^
        e, str_statement, effective_parameters, cursor, context
        ^^^^^^^^^^^^^^^^^^^^^^^^^^^^^^^^^^^^^^^^^^^^^^^^^^^^^^^
    )
    ^
  File "/Users/malandru/.pyenv/versions/3.13.1/lib/python3.13/site-packages/sqlalchemy/engine/base.py", line 2352, in _handle_dbapi_exception
    raise sqlalchemy_exception.with_traceback(exc_info[2]) from e
  File "/Users/malandru/.pyenv/versions/3.13.1/lib/python3.13/site-packages/sqlalchemy/engine/base.py", line 1964, in _exec_single_context
    self.dialect.do_execute(
    ~~~~~~~~~~~~~~~~~~~~~~~^
        cursor, str_statement, effective_parameters, context
        ^^^^^^^^^^^^^^^^^^^^^^^^^^^^^^^^^^^^^^^^^^^^^^^^^^^^
    )
    ^
  File "/Users/malandru/.pyenv/versions/3.13.1/lib/python3.13/site-packages/sqlalchemy/engine/default.py", line 942, in do_execute
    cursor.execute(statement, parameters)
    ~~~~~~~~~~~~~~^^^^^^^^^^^^^^^^^^^^^^^
sqlalchemy.exc.OperationalError: (sqlite3.OperationalError) no such table: user
[SQL: SELECT user.id, user.username, user.email, user.password_hash, user.about_me, user.last_seen 
FROM user 
WHERE user.username = ?]
[parameters: ('Andy',)]
(Background on this error at: https://sqlalche.me/e/20/e3q8)
2025-03-11 11:49:50,608 INFO: Microblog startup [in /Users/malandru/microblog_2.0/app/__init__.py:59]
2025-03-11 11:49:50,942 INFO: Microblog startup [in /Users/malandru/microblog_2.0/app/__init__.py:59]
2025-03-11 11:50:15,878 INFO: Microblog startup [in /Users/malandru/microblog_2.0/app/__init__.py:59]
